Traceback (most recent call last):
  File "../get_predictors.py", line 298, in <module>
    main()
  File "../get_predictors.py", line 288, in main
    get_stats(args.dataset, args.input_path, args.mlm_model, args.ar_model, args.language, args.mask_type)
  File "../get_predictors.py", line 266, in get_stats
    pairwise_stats = get_pairwise_stats(split_sent, text_id, sent_id, mlm_model, ar_surps, freqs, mask_type)
  File "../get_predictors.py", line 169, in get_pairwise_stats
    tokenizer = BertTokenizer.from_pretrained(MODEL_NAME[mlm_model])
  File "/cluster/home/ewilcox/miniconda3/envs/mi-vs-syntax/lib/python3.7/site-packages/transformers/tokenization_utils_base.py", line 1750, in from_pretrained
    _commit_hash=commit_hash,
  File "/cluster/home/ewilcox/miniconda3/envs/mi-vs-syntax/lib/python3.7/site-packages/transformers/utils/hub.py", line 420, in cached_file
    local_files_only=local_files_only,
  File "/cluster/home/ewilcox/miniconda3/envs/mi-vs-syntax/lib/python3.7/site-packages/huggingface_hub/utils/_validators.py", line 124, in _inner_fn
    return fn(*args, **kwargs)
  File "/cluster/home/ewilcox/miniconda3/envs/mi-vs-syntax/lib/python3.7/site-packages/huggingface_hub/file_download.py", line 1148, in hf_hub_download
    with open(ref_path) as f:
FileNotFoundError: [Errno 2] No such file or directory: '/cluster/home/ewilcox/.cache/huggingface/hub/models--DeepPavlov--rubert-base-cased/refs/main'
